Workbook

Sheet Plan1
B3: MESA 01 | F3: MESA 02
B4: NOME | C4: ADULTO | D4: CRIANÇA | F4: NOME | G4: ADULTO | H4: CRIANÇA
B5: 1- | F5: 1-
B6: 2- | F6: 2-
B7: 3- | F7: 3-
B8: 4- | F8: 4-
B9: 5- | F9: 5-
B10: 6- | F10: 6-
B11: 7- | F11: 7-
B12: 8- | F12: 8-
B13: 9- | F13: 9-
B14: 10- | F14: 10-
B15: Quantidade: | C15: =SUM(C5:C14) | D15: =SUM(D5:D14) | F15: Quantidade: | G15: =SUM(G5:G14) | H15: =SUM(H5:H14)
B16: TOTAL | C16: =SUM(C15:D15) | F16: TOTAL | G16: =SUM(G15:H15)
B19: MESA 03 | F19: MESA 04
B20: NOME | C20: ADULTO | D20: CRIANÇA | F20: NOME | G20: ADULTO | H20: CRIANÇA
B21: 1- | F21: 1-
B22: 2- | F22: 2-
B23: 3- | F23: 3-
B24: 4- | F24: 4-
B25: 5- | F25: 5-
B26: 6- | F26: 6-
B27: 7- | F27: 7-
B28: 8- | F28: 8-
B29: 9- | F29: 9-
B30: 10- | F30: 10-
B31: QUANTIDADE | C31: =SUM(C21:C30) | D31: =SUM(D21:D30) | F31: QUANTIDADE | G31: =SUM(G21:G30) | H31: =SUM(H21:H30)
B32: TOTAL | C32: =SUM(C31:D31) | F32: TOTAL | G32: =SUM(G31:H31)
B35: MESA 05 | F35: MESA 06
B36: NOME | C36: ADULTO | D36: CRIANÇA | F36: NOME | G36: ADULTO | H36: CRIANÇA
B37: 1- | F37: 1-
B38: 2- | F38: 2-
B39: 3- | F39: 3-
B40: 4- | F40: 4-
B41: 5- | F41: 5-
B42: 6- | F42: 6-
B43: 7- | F43: 7-
B44: 8- | F44: 8-
B45: 9- | F45: 9-
B46: 10- | F46: 10-
...

Sheet Plan2
A1: Nome | B1: Pessoas | C1: Telefone | D1: Mesa | F1: Para passar para o painel:
A2: =IFERROR(IF(ISNUMBER(VALUE(LEFT(Plan1!B5,FIND("-",Plan1!B5)-1))),TRIM(MID(Plan1!B5,FIND("-",Plan1!B5)+1,200)),TRIM(Plan1!B5)),TRIM(Plan1!B5)) | B2: =IF(A2="","",MAX(1,N(Plan1!C5)+N(Plan1!D5))) | D2: =IF(A2="","",TRIM(Plan1!$B$3)) | F2: 1. Selecione as colunas A até D (clique no A e arraste até o D).
A3: =IFERROR(IF(ISNUMBER(VALUE(LEFT(Plan1!B6,FIND("-",Plan1!B6)-1))),TRIM(MID(Plan1!B6,FIND("-",Plan1!B6)+1,200)),TRIM(Plan1!B6)),TRIM(Plan1!B6)) | B3: =IF(A3="","",MAX(1,N(Plan1!C6)+N(Plan1!D6))) | D3: =IF(A3="","",TRIM(Plan1!$B$3)) | F3: 2. Copie (Ctrl+C).
A4: =IFERROR(IF(ISNUMBER(VALUE(LEFT(Plan1!B7,FIND("-",Plan1!B7)-1))),TRIM(MID(Plan1!B7,FIND("-",Plan1!B7)+1,200)),TRIM(Plan1!B7)),TRIM(Plan1!B7)) | B4: =IF(A4="","",MAX(1,N(Plan1!C7)+N(Plan1!D7))) | D4: =IF(A4="","",TRIM(Plan1!$B$3)) | F4: 3. No painel: festa → Convidados → "Adicionar vários de uma vez" → cole (Ctrl+V).
A5: =IFERROR(IF(ISNUMBER(VALUE(LEFT(Plan1!B8,FIND("-",Plan1!B8)-1))),TRIM(MID(Plan1!B8,FIND("-",Plan1!B8)+1,200)),TRIM(Plan1!B8)),TRIM(Plan1!B8)) | B5: =IF(A5="","",MAX(1,N(Plan1!C8)+N(Plan1!D8))) | D5: =IF(A5="","",TRIM(Plan1!$B$3)) | F5: 4. Confira a prévia e clique em Adicionar.
A6: =IFERROR(IF(ISNUMBER(VALUE(LEFT(Plan1!B9,FIND("-",Plan1!B9)-1))),TRIM(MID(Plan1!B9,FIND("-",Plan1!B9)+1,200)),TRIM(Plan1!B9)),TRIM(Plan1!B9)) | B6: =IF(A6="","",MAX(1,N(Plan1!C9)+N(Plan1!D9))) | D6: =IF(A6="","",TRIM(Plan1!$B$3))
A7: =IFERROR(IF(ISNUMBER(VALUE(LEFT(Plan1!B10,FIND("-",Plan1!B10)-1))),TRIM(MID(Plan1!B10,FIND("-",Plan1!B10)+1,200)),TRIM(Plan1!B10)),TRIM(Plan1!B10)) | B7: =IF(A7="","",MAX(1,N(Plan1!C10)+N(Plan1!D10))) | D7: =IF(A7="","",TRIM(Plan1!$B$3)) | F7: Esta aba se preenche sozinha com o que foi escrito na Plan1. Não precisa digitar aqui.
A8: =IFERROR(IF(ISNUMBER(VALUE(LEFT(Plan1!B11,FIND("-",Plan1!B11)-1))),TRIM(MID(Plan1!B11,FIND("-",Plan1!B11)+1,200)),TRIM(Plan1!B11)),TRIM(Plan1!B11)) | B8: =IF(A8="","",MAX(1,N(Plan1!C11)+N(Plan1!D11))) | D8: =IF(A8="","",TRIM(Plan1!$B$3)) | F8: Pessoas = ADULTO + CRIANÇA da linha (1 se estiverem vazios).
A9: =IFERROR(IF(ISNUMBER(VALUE(LEFT(Plan1!B12,FIND("-",Plan1!B12)-1))),TRIM(MID(Plan1!B12,FIND("-",Plan1!B12)+1,200)),TRIM(Plan1!B12)),TRIM(Plan1!B12)) | B9: =IF(A9="","",MAX(1,N(Plan1!C12)+N(Plan1!D12))) | D9: =IF(A9="","",TRIM(Plan1!$B$3)) | F9: Quem já está no painel só muda de mesa; mesa que não existe no painel é criada.
A10: =IFERROR(IF(ISNUMBER(VALUE(LEFT(Plan1!B13,FIND("-",Plan1!B13)-1))),TRIM(MID(Plan1!B13,FIND("-",Plan1!B13)+1,200)),TRIM(Plan1!B13)),TRIM(Plan1!B13)) | B10: =IF(A10="","",MAX(1,N(Plan1!C13)+N(Plan1!D13))) | D10: =IF(A10="","",TRIM(Plan1!$B$3))
A11: =IFERROR(IF(ISNUMBER(VALUE(LEFT(Plan1!B14,FIND("-",Plan1!B14)-1))),TRIM(MID(Plan1!B14,FIND("-",Plan1!B14)+1,200)),TRIM(Plan1!B14)),TRIM(Plan1!B14)) | B11: =IF(A11="","",MAX(1,N(Plan1!C14)+N(Plan1!D14))) | D11: =IF(A11="","",TRIM(Plan1!$B$3))
A12: =IFERROR(IF(ISNUMBER(VALUE(LEFT(Plan1!F5,FIND("-",Plan1!F5)-1))),TRIM(MID(Plan1!F5,FIND("-",Plan1!F5)+1,200)),TRIM(Plan1!F5)),TRIM(Plan1!F5)) | B12: =IF(A12="","",MAX(1,N(Plan1!G5)+N(Plan1!H5))) | D12: =IF(A12="","",TRIM(Plan1!$F$3))
A13: =IFERROR(IF(ISNUMBER(VALUE(LEFT(Plan1!F6,FIND("-",Plan1!F6)-1))),TRIM(MID(Plan1!F6,FIND("-",Plan1!F6)+1,200)),TRIM(Plan1!F6)),TRIM(Plan1!F6)) | B13: =IF(A13="","",MAX(1,N(Plan1!G6)+N(Plan1!H6))) | D13: =IF(A13="","",TRIM(Plan1!$F$3))
A14: =IFERROR(IF(ISNUMBER(VALUE(LEFT(Plan1!F7,FIND("-",Plan1!F7)-1))),TRIM(MID(Plan1!F7,FIND("-",Plan1!F7)+1,200)),TRIM(Plan1!F7)),TRIM(Plan1!F7)) | B14: =IF(A14="","",MAX(1,N(Plan1!G7)+N(Plan1!H7))) | D14: =IF(A14="","",TRIM(Plan1!$F$3))
A15: =IFERROR(IF(ISNUMBER(VALUE(LEFT(Plan1!F8,FIND("-",Plan1!F8)-1))),TRIM(MID(Plan1!F8,FIND("-",Plan1!F8)+1,200)),TRIM(Plan1!F8)),TRIM(Plan1!F8)) | B15: =IF(A15="","",MAX(1,N(Plan1!G8)+N(Plan1!H8))) | D15: =IF(A15="","",TRIM(Plan1!$F$3))
A16: =IFERROR(IF(ISNUMBER(VALUE(LEFT(Plan1!F9,FIND("-",Plan1!F9)-1))),TRIM(MID(Plan1!F9,FIND("-",Plan1!F9)+1,200)),TRIM(Plan1!F9)),TRIM(Plan1!F9)) | B16: =IF(A16="","",MAX(1,N(Plan1!G9)+N(Plan1!H9))) | D16: =IF(A16="","",TRIM(Plan1!$F$3))
A17: =IFERROR(IF(ISNUMBER(VALUE(LEFT(Plan1!F10,FIND("-",Plan1!F10)-1))),TRIM(MID(Plan1!F10,FIND("-",Plan1!F10)+1,200)),TRIM(Plan1!F10)),TRIM(Plan1!F10)) | B17: =IF(A17="","",MAX(1,N(Plan1!G10)+N(Plan1!H10))) | D17: =IF(A17="","",TRIM(Plan1!$F$3))
A18: =IFERROR(IF(ISNUMBER(VALUE(LEFT(Plan1!F11,FIND("-",Plan1!F11)-1))),TRIM(MID(Plan1!F11,FIND("-",Plan1!F11)+1,200)),TRIM(Plan1!F11)),TRIM(Plan1!F11)) | B18: =IF(A18="","",MAX(1,N(Plan1!G11)+N(Plan1!H11))) | D18: =IF(A18="","",TRIM(Plan1!$F$3))
A19: =IFERROR(IF(ISNUMBER(VALUE(LEFT(Plan1!F12,FIND("-",Plan1!F12)-1))),TRIM(MID(Plan1!F12,FIND("-",Plan1!F12)+1,200)),TRIM(Plan1!F12)),TRIM(Plan1!F12)) | B19: =IF(A19="","",MAX(1,N(Plan1!G12)+N(Plan1!H12))) | D19: =IF(A19="","",TRIM(Plan1!$F$3))
A20: =IFERROR(IF(ISNUMBER(VALUE(LEFT(Plan1!F13,FIND("-",Plan1!F13)-1))),TRIM(MID(Plan1!F13,FIND("-",Plan1!F13)+1,200)),TRIM(Plan1!F13)),TRIM(Plan1!F13)) | B20: =IF(A20="","",MAX(1,N(Plan1!G13)+N(Plan1!H13))) | D20: =IF(A20="","",TRIM(Plan1!$F$3))
A21: =IFERROR(IF(ISNUMBER(VALUE(LEFT(Plan1!F14,FIND("-",Plan1!F14)-1))),TRIM(MID(Plan1!F14,FIND("-",Plan1!F14)+1,200)),TRIM(Plan1!F14)),TRIM(Plan1!F14)) | B21: =IF(A21="","",MAX(1,N(Plan1!G14)+N(Plan1!H14))) | D21: =IF(A21="","",TRIM(Plan1!$F$3))
A22: =IFERROR(IF(ISNUMBER(VALUE(LEFT(Plan1!B21,FIND("-",Plan1!B21)-1))),TRIM(MID(Plan1!B21,FIND("-",Plan1!B21)+1,200)),TRIM(Plan1!B21)),TRIM(Plan1!B21)) | B22: =IF(A22="","",MAX(1,N(Plan1!C21)+N(Plan1!D21))) | D22: =IF(A22="","",TRIM(Plan1!$B$19))
A23: =IFERROR(IF(ISNUMBER(VALUE(LEFT(Plan1!B22,FIND("-",Plan1!B22)-1))),TRIM(MID(Plan1!B22,FIND("-",Plan1!B22)+1,200)),TRIM(Plan1!B22)),TRIM(Plan1!B22)) | B23: =IF(A23="","",MAX(1,N(Plan1!C22)+N(Plan1!D22))) | D23: =IF(A23="","",TRIM(Plan1!$B$19))
A24: =IFERROR(IF(ISNUMBER(VALUE(LEFT(Plan1!B23,FIND("-",Plan1!B23)-1))),TRIM(MID(Plan1!B23,FIND("-",Plan1!B23)+1,200)),TRIM(Plan1!B23)),TRIM(Plan1!B23)) | B24: =IF(A24="","",MAX(1,N(Plan1!C23)+N(Plan1!D23))) | D24: =IF(A24="","",TRIM(Plan1!$B$19))
A25: =IFERROR(IF(ISNUMBER(VALUE(LEFT(Plan1!B24,FIND("-",Plan1!B24)-1))),TRIM(MID(Plan1!B24,FIND("-",Plan1!B24)+1,200)),TRIM(Plan1!B24)),TRIM(Plan1!B24)) | B25: =IF(A25="","",MAX(1,N(Plan1!C24)+N(Plan1!D24))) | D25: =IF(A25="","",TRIM(Plan1!$B$19))
A26: =IFERROR(IF(ISNUMBER(VALUE(LEFT(Plan1!B25,FIND("-",Plan1!B25)-1))),TRIM(MID(Plan1!B25,FIND("-",Plan1!B25)+1,200)),TRIM(Plan1!B25)),TRIM(Plan1!B25)) | B26: =IF(A26="","",MAX(1,N(Plan1!C25)+N(Plan1!D25))) | D26: =IF(A26="","",TRIM(Plan1!$B$19))
A27: =IFERROR(IF(ISNUMBER(VALUE(LEFT(Plan1!B26,FIND("-",Plan1!B26)-1))),TRIM(MID(Plan1!B26,FIND("-",Plan1!B26)+1,200)),TRIM(Plan1!B26)),TRIM(Plan1!B26)) | B27: =IF(A27="","",MAX(1,N(Plan1!C26)+N(Plan1!D26))) | D27: =IF(A27="","",TRIM(Plan1!$B$19))
A28: =IFERROR(IF(ISNUMBER(VALUE(LEFT(Plan1!B27,FIND("-",Plan1!B27)-1))),TRIM(MID(Plan1!B27,FIND("-",Plan1!B27)+1,200)),TRIM(Plan1!B27)),TRIM(Plan1!B27)) | B28: =IF(A28="","",MAX(1,N(Plan1!C27)+N(Plan1!D27))) | D28: =IF(A28="","",TRIM(Plan1!$B$19))
A29: =IFERROR(IF(ISNUMBER(VALUE(LEFT(Plan1!B28,FIND("-",Plan1!B28)-1))),TRIM(MID(Plan1!B28,FIND("-",Plan1!B28)+1,200)),TRIM(Plan1!B28)),TRIM(Plan1!B28)) | B29: =IF(A29="","",MAX(1,N(Plan1!C28)+N(Plan1!D28))) | D29: =IF(A29="","",TRIM(Plan1!$B$19))
A30: =IFERROR(IF(ISNUMBER(VALUE(LEFT(Plan1!B29,FIND("-",Plan1!B29)-1))),TRIM(MID(Plan1!B29,FIND("-",Plan1!B29)+1,200)),TRIM(Plan1!B29)),TRIM(Plan1!B29)) | B30: =IF(A30="","",MAX(1,N(Plan1!C29)+N(Plan1!D29))) | D30: =IF(A30="","",TRIM(Plan1!$B$19))
A31: =IFERROR(IF(ISNUMBER(VALUE(LEFT(Plan1!B30,FIND("-",Plan1!B30)-1))),TRIM(MID(Plan1!B30,FIND("-",Plan1!B30)+1,200)),TRIM(Plan1!B30)),TRIM(Plan1!B30)) | B31: =IF(A31="","",MAX(1,N(Plan1!C30)+N(Plan1!D30))) | D31: =IF(A31="","",TRIM(Plan1!$B$19))
A32: =IFERROR(IF(ISNUMBER(VALUE(LEFT(Plan1!F21,FIND("-",Plan1!F21)-1))),TRIM(MID(Plan1!F21,FIND("-",Plan1!F21)+1,200)),TRIM(Plan1!F21)),TRIM(Plan1!F21)) | B32: =IF(A32="","",MAX(1,N(Plan1!G21)+N(Plan1!H21))) | D32: =IF(A32="","",TRIM(Plan1!$F$19))
A33: =IFERROR(IF(ISNUMBER(VALUE(LEFT(Plan1!F22,FIND("-",Plan1!F22)-1))),TRIM(MID(Plan1!F22,FIND("-",Plan1!F22)+1,200)),TRIM(Plan1!F22)),TRIM(Plan1!F22)) | B33: =IF(A33="","",MAX(1,N(Plan1!G22)+N(Plan1!H22))) | D33: =IF(A33="","",TRIM(Plan1!$F$19))
A34: =IFERROR(IF(ISNUMBER(VALUE(LEFT(Plan1!F23,FIND("-",Plan1!F23)-1))),TRIM(MID(Plan1!F23,FIND("-",Plan1!F23)+1,200)),TRIM(Plan1!F23)),TRIM(Plan1!F23)) | B34: =IF(A34="","",MAX(1,N(Plan1!G23)+N(Plan1!H23))) | D34: =IF(A34="","",TRIM(Plan1!$F$19))
A35: =IFERROR(IF(ISNUMBER(VALUE(LEFT(Plan1!F24,FIND("-",Plan1!F24)-1))),TRIM(MID(Plan1!F24,FIND("-",Plan1!F24)+1,200)),TRIM(Plan1!F24)),TRIM(Plan1!F24)) | B35: =IF(A35="","",MAX(1,N(Plan1!G24)+N(Plan1!H24))) | D35: =IF(A35="","",TRIM(Plan1!$F$19))
A36: =IFERROR(IF(ISNUMBER(VALUE(LEFT(Plan1!F25,FIND("-",Plan1!F25)-1))),TRIM(MID(Plan1!F25,FIND("-",Plan1!F25)+1,200)),TRIM(Plan1!F25)),TRIM(Plan1!F25)) | B36: =IF(A36="","",MAX(1,N(Plan1!G25)+N(Plan1!H25))) | D36: =IF(A36="","",TRIM(Plan1!$F$19))
A37: =IFERROR(IF(ISNUMBER(VALUE(LEFT(Plan1!F26,FIND("-",Plan1!F26)-1))),TRIM(MID(Plan1!F26,FIND("-",Plan1!F26)+1,200)),TRIM(Plan1!F26)),TRIM(Plan1!F26)) | B37: =IF(A37="","",MAX(1,N(Plan1!G26)+N(Plan1!H26))) | D37: =IF(A37="","",TRIM(Plan1!$F$19))
A38: =IFERROR(IF(ISNUMBER(VALUE(LEFT(Plan1!F27,FIND("-",Plan1!F27)-1))),TRIM(MID(Plan1!F27,FIND("-",Plan1!F27)+1,200)),TRIM(Plan1!F27)),TRIM(Plan1!F27)) | B38: =IF(A38="","",MAX(1,N(Plan1!G27)+N(Plan1!H27))) | D38: =IF(A38="","",TRIM(Plan1!$F$19))
A39: =IFERROR(IF(ISNUMBER(VALUE(LEFT(Plan1!F28,FIND("-",Plan1!F28)-1))),TRIM(MID(Plan1!F28,FIND("-",Plan1!F28)+1,200)),TRIM(Plan1!F28)),TRIM(Plan1!F28)) | B39: =IF(A39="","",MAX(1,N(Plan1!G28)+N(Plan1!H28))) | D39: =IF(A39="","",TRIM(Plan1!$F$19))
A40: =IFERROR(IF(ISNUMBER(VALUE(LEFT(Plan1!F29,FIND("-",Plan1!F29)-1))),TRIM(MID(Plan1!F29,FIND("-",Plan1!F29)+1,200)),TRIM(Plan1!F29)),TRIM(Plan1!F29)) | B40: =IF(A40="","",MAX(1,N(Plan1!G29)+N(Plan1!H29))) | D40: =IF(A40="","",TRIM(Plan1!$F$19))
...

Sheet Plan3
